Workbook

Sheet README
A1: SMB4 Grade Calculator + Fictional Player Generator
A3: This workbook is designed for upload to Google Sheets.
A5: Tabs:
A6: - Calculator: enter player attributes and get predicted grade.
A7: - Generator: pick target grade + context and generate random stat lines.
A8: - Archetype_Presets: roster templates for balanced/power/speed-defense/bullpen-heavy teams.
A9: - Trait_Polarity / PrimaryAdj / SecondaryAdj: lookup tables.
A11: Model factors included:
A12: - Primary position
A13: - Secondary position
A14: - Bats / Throws
A15: - Positive vs Negative traits
... A20: S, A+, A, A-, B+, B, B-, C+, C, C-, D+, D, D-, E+, E, E-, F

Sheet Grade_Scale
A1: GradeIdx | B1: Grade | D1: Grade | E1: GradeIdx
A2: 0 | B2: F | D2: S | E2: 16
A3: 1 | B3: E- | D3: A+ | E3: 15
A4: 2 | B4: E | D4: A | E4: 14
A5: 3 | B5: E+ | D5: A- | E5: 13
A6: 4 | B6: D- | D6: B+ | E6: 12
A7: 5 | B7: D | D7: B | E7: 11
A8: 6 | B8: D+ | D8: B- | E8: 10
A9: 7 | B9: C- | D9: C+ | E9: 9
A10: 8 | B10: C | D10: C | E10: 8
A11: 9 | B11: C+ | D11: C- | E11: 7
A12: 10 | B12: B- | D12: D+ | E12: 6
A13: 11 | B13: B | D13: D | E13: 5
... A18: 16 | B18: S | D18: F | E18: 0

Sheet Archetype_Presets
A1: Archetype | B1: C | C1: 1B | D1: 2B | E1: 3B | F1: SS | G1: LF | H1: CF | I1: RF | J1: SP | K1: SP/RP | L1: RP | M1: CP | N1: Total
A2: balanced | B2: 2 | C2: 2 | D2: 2 | E2: 1 | F2: 1 | G2: 2 | H2: 1 | I2: 2 | J2: 4 | K2: 1 | L2: 3 | M2: 1 | N2: 22
A3: power-heavy | B3: 2 | C3: 3 | D3: 1 | E3: 2 | F3: 1 | G3: 2 | H3: 1 | I3: 2 | J3: 4 | K3: 1 | L3: 2 | M3: 1 | N3: 22
A4: speed-defense | B4: 2 | C4: 1 | D4: 2 | E4: 1 | F4: 2 | G4: 1 | H4: 2 | I4: 1 | J4: 4 | K4: 1 | L4: 4 | M4: 1 | N4: 22
A5: bullpen-heavy | B5: 2 | C5: 1 | D5: 2 | E5: 1 | F5: 2 | G5: 1 | H5: 1 | I5: 1 | J5: 3 | K5: 2 | L5: 5 | M5: 1 | N5: 22

Sheet Trait_Polarity
A1: Trait | B1: PosFlag | C1: NegFlag | D1: Polarity
A2: Ace Exterminator | B2: 1 | C2: 0 | D2: Positive
A3: BB Prone | B3: 0 | C3: 1 | D3: Negative
A4: Bad Ball Hitter | B4: 1 | C4: 0 | D4: Positive
A5: Bad Jumps | B5: 0 | C5: 1 | D5: Negative
A6: Base Jogger | B6: 0 | C6: 1 | D6: Negative
A7: Base Rounder | B7: 1 | C7: 0 | D7: Positive
A8: Big Hack | B8: 1 | C8: 0 | D8: Positive
A9: Bunter | B9: 1 | C9: 0 | D9: Positive
A10: Butter Fingers | B10: 0 | C10: 1 | D10: Negative
A11: CON vs LHP | B11: 1 | C11: 0 | D11: Positive
A12: CON vs RHP | B12: 1 | C12: 0 | D12: Positive
A13: Cannon Arm | B13: 1 | C13: 0 | D13: Positive
... A74: Wild Thrower | B74: 0 | C74: 1 | D74: Negative

Sheet Hitter_PrimaryAdj
A1: PrimaryPos | B1: Adj
A2: 1B | B2: 0
A3: 2B | B3: 0.051
A4: 3B | B4: -0.395
A5: C | B5: 0.476
A6: CF | B6: 0.072
A7: LF | B7: -0.119
A8: RF | B8: 0.014
A9: SS | B9: -0.136

Sheet Pitcher_RoleAdj
A1: PrimaryPos | B1: Adj
A2: CP | B2: -0.431
A3: RP | B3: -0.265
A4: SP | B4: 0
A5: SP/RP | B5: -0.353

Sheet SecondaryAdj
A1: SecondaryPos | B1: Adj
A2: (none) | B2: 0
A3: 1B | B3: 0.104
A4: 1B/OF | B4: 0.126
A5: 2B | B5: 0.481
A6: 3B | B6: 0.268
A7: C | B7: -0.058
A8: IF | B8: 0.262
A9: IF/OF | B9: 0.369
A10: LF | B10: 0.004
A11: OF | B11: 0.196
A12: RF | B12: 0.159
A13: SS | B13: 0.296

Sheet Calculator
A1: Name | B1: PrimaryPos | C1: SecondaryPos | D1: Bats | E1: Throws | F1: Trait1 | G1: Trait2 | H1: POW | I1: CON | J1: SPD | K1: FLD | L1: ARM | M1: VEL | N1: JNK | O1: ACC | P1: PlayerType | Q1: PosTraits | R1: NegTraits | S1: BaseWeighted | T1: PrimaryAdj | U1: SecondaryAdj | V1: Points | W1: GradeIdx | X1: Grade | Y1: TargetGrade | Z1: DeltaIdx (Pred-Target) | AA1: Notes
P2: =IF(OR(B2="SP",B2="RP",B2="CP",B2="SP/RP"),"P","H") | Q2: =IF(F2="",0,IFNA(VLOOKUP(F2,Trait_Polarity!$A:$C,2,FALSE),0))+IF(G2="",0,IFNA(VLOOKUP(G2,Trait_Polarity!$A:$C,2,FALSE),0)) | R2: =IF(F2="",0,IFNA(VLOOKUP(F2,Trait_Polarity!$A:$C,3,FALSE),0))+IF(G2="",0,IFNA(VLOOKUP(G2,Trait_Polarity!$A:$C,3,FALSE),0)) | S2: =IF(P2="P",(M2+N2+O2)/3,0.3*H2+0.3*I2+0.2*J2+0.1*K2+0.1*L2) | T2: =IF(P2="P",IFNA(VLOOKUP(B2,Pitcher_RoleAdj!$A:$B,2,FALSE),0),IFNA(VLOOKUP(B2,Hitter_PrimaryAdj!$A:$B,2,FALSE),0)) | U2: =IFNA(VLOOKUP(IF(C2="","(none)",C2),SecondaryAdj!$A:$B,2,FALSE),0) | V2: =IF(P2="P",0.7780+0.1628*S2+0.2957*Q2-0.1912*R2-0.1512*IF(D2="S",1,0)+0.1600*IF(E2="L",1,0)+0.0091*H2+0.0124*I2+0.0017*J2+T2+U2,-0.8294+0.1849*S2+0.1750*Q2-0.2969*R2+0.6924*IF(D2="S",1,0)+0.0457*IF(E2="L",1,0)+T2+U2) | W2: =MAX(0,MIN(16,ROUND(V2,0))) | X2: =IFNA(VLOOKUP(W2,Grade_Scale!$A:$B,2,FALSE),"F") | Z2: =IF(Y2="","",W2-IFNA(VLOOKUP(Y2,Grade_Scale!$D:$E,2,FALSE),""))
P3: =IF(OR(B3="SP",B3="RP",B3="CP",B3="SP/RP"),"P","H") | Q3: =IF(F3="",0,IFNA(VLOOKUP(F3,Trait_Polarity!$A:$C,2,FALSE),0))+IF(G3="",0,IFNA(VLOOKUP(G3,Trait_Polarity!$A:$C,2,FALSE),0)) | R3: =IF(F3="",0,IFNA(VLOOKUP(F3,Trait_Polarity!$A:$C,3,FALSE),0))+IF(G3="",0,IFNA(VLOOKUP(G3,Trait_Polarity!$A:$C,3,FALSE),0)) | S3: =IF(P3="P",(M3+N3+O3)/3,0.3*H3+0.3*I3+0.2*J3+0.1*K3+0.1*L3) | T3: =IF(P3="P",IFNA(VLOOKUP(B3,Pitcher_RoleAdj!$A:$B,2,FALSE),0),IFNA(VLOOKUP(B3,Hitter_PrimaryAdj!$A:$B,2,FALSE),0)) | U3: =IFNA(VLOOKUP(IF(C3="","(none)",C3),SecondaryAdj!$A:$B,2,FALSE),0) | V3: =IF(P3="P",0.7780+0.1628*S3+0.2957*Q3-0.1912*R3-0.1512*IF(D3="S",1,0)+0.1600*IF(E3="L",1,0)+0.0091*H3+0.0124*I3+0.0017*J3+T3+U3,-0.8294+0.1849*S3+0.1750*Q3-0.2969*R3+0.6924*IF(D3="S",1,0)+0.0457*IF(E3="L",1,0)+T3+U3) | W3: =MAX(0,MIN(16,ROUND(V3,0))) | X3: =IFNA(VLOOKUP(W3,Grade_Scale!$A:$B,2,FALSE),"F") | Z3: =IF(Y3="","",W3-IFNA(VLOOKUP(Y3,Grade_Scale!$D:$E,2,FALSE),""))
P4: =IF(OR(B4="SP",B4="RP",B4="CP",B4="SP/RP"),"P","H") | Q4: =IF(F4="",0,IFNA(VLOOKUP(F4,Trait_Polarity!$A:$C,2,FALSE),0))+IF(G4="",0,IFNA(VLOOKUP(G4,Trait_Polarity!$A:$C,2,FALSE),0)) | R4: =IF(F4="",0,IFNA(VLOOKUP(F4,Trait_Polarity!$A:$C,3,FALSE),0))+IF(G4="",0,IFNA(VLOOKUP(G4,Trait_Polarity!$A:$C,3,FALSE),0)) | S4: =IF(P4="P",(M4+N4+O4)/3,0.3*H4+0.3*I4+0.2*J4+0.1*K4+0.1*L4) | T4: =IF(P4="P",IFNA(VLOOKUP(B4,Pitcher_RoleAdj!$A:$B,2,FALSE),0),IFNA(VLOOKUP(B4,Hitter_PrimaryAdj!$A:$B,2,FALSE),0)) | U4: =IFNA(VLOOKUP(IF(C4="","(none)",C4),SecondaryAdj!$A:$B,2,FALSE),0) | V4: =IF(P4="P",0.7780+0.1628*S4+0.2957*Q4-0.1912*R4-0.1512*IF(D4="S",1,0)+0.1600*IF(E4="L",1,0)+0.0091*H4+0.0124*I4+0.0017*J4+T4+U4,-0.8294+0.1849*S4+0.1750*Q4-0.2969*R4+0.6924*IF(D4="S",1,0)+0.0457*IF(E4="L",1,0)+T4+U4) | W4: =MAX(0,MIN(16,ROUND(V4,0))) | X4: =IFNA(VLOOKUP(W4,Grade_Scale!$A:$B,2,FALSE),"F") | Z4: =IF(Y4="","",W4-IFNA(VLOOKUP(Y4,Grade_Scale!$D:$E,2,FALSE),""))
P5: =IF(OR(B5="SP",B5="RP",B5="CP",B5="SP/RP"),"P","H") | Q5: =IF(F5="",0,IFNA(VLOOKUP(F5,Trait_Polarity!$A:$C,2,FALSE),0))+IF(G5="",0,IFNA(VLOOKUP(G5,Trait_Polarity!$A:$C,2,FALSE),0)) | R5: =IF(F5="",0,IFNA(VLOOKUP(F5,Trait_Polarity!$A:$C,3,FALSE),0))+IF(G5="",0,IFNA(VLOOKUP(G5,Trait_Polarity!$A:$C,3,FALSE),0)) | S5: =IF(P5="P",(M5+N5+O5)/3,0.3*H5+0.3*I5+0.2*J5+0.1*K5+0.1*L5) | T5: =IF(P5="P",IFNA(VLOOKUP(B5,Pitcher_RoleAdj!$A:$B,2,FALSE),0),IFNA(VLOOKUP(B5,Hitter_PrimaryAdj!$A:$B,2,FALSE),0)) | U5: =IFNA(VLOOKUP(IF(C5="","(none)",C5),SecondaryAdj!$A:$B,2,FALSE),0) | V5: =IF(P5="P",0.7780+0.1628*S5+0.2957*Q5-0.1912*R5-0.1512*IF(D5="S",1,0)+0.1600*IF(E5="L",1,0)+0.0091*H5+0.0124*I5+0.0017*J5+T5+U5,-0.8294+0.1849*S5+0.1750*Q5-0.2969*R5+0.6924*IF(D5="S",1,0)+0.0457*IF(E5="L",1,0)+T5+U5) | W5: =MAX(0,MIN(16,ROUND(V5,0))) | X5: =IFNA(VLOOKUP(W5,Grade_Scale!$A:$B,2,FALSE),"F") | Z5: =IF(Y5="","",W5-IFNA(VLOOKUP(Y5,Grade_Scale!$D:$E,2,FALSE),""))
P6: =IF(OR(B6="SP",B6="RP",B6="CP",B6="SP/RP"),"P","H") | Q6: =IF(F6="",0,IFNA(VLOOKUP(F6,Trait_Polarity!$A:$C,2,FALSE),0))+IF(G6="",0,IFNA(VLOOKUP(G6,Trait_Polarity!$A:$C,2,FALSE),0)) | R6: =IF(F6="",0,IFNA(VLOOKUP(F6,Trait_Polarity!$A:$C,3,FALSE),0))+IF(G6="",0,IFNA(VLOOKUP(G6,Trait_Polarity!$A:$C,3,FALSE),0)) | S6: =IF(P6="P",(M6+N6+O6)/3,0.3*H6+0.3*I6+0.2*J6+0.1*K6+0.1*L6) | T6: =IF(P6="P",IFNA(VLOOKUP(B6,Pitcher_RoleAdj!$A:$B,2,FALSE),0),IFNA(VLOOKUP(B6,Hitter_PrimaryAdj!$A:$B,2,FALSE),0)) | U6: =IFNA(VLOOKUP(IF(C6="","(none)",C6),SecondaryAdj!$A:$B,2,FALSE),0) | V6: =IF(P6="P",0.7780+0.1628*S6+0.2957*Q6-0.1912*R6-0.1512*IF(D6="S",1,0)+0.1600*IF(E6="L",1,0)+0.0091*H6+0.0124*I6+0.0017*J6+T6+U6,-0.8294+0.1849*S6+0.1750*Q6-0.2969*R6+0.6924*IF(D6="S",1,0)+0.0457*IF(E6="L",1,0)+T6+U6) | W6: =MAX(0,MIN(16,ROUND(V6,0))) | X6: =IFNA(VLOOKUP(W6,Grade_Scale!$A:$B,2,FALSE),"F") | Z6: =IF(Y6="","",W6-IFNA(VLOOKUP(Y6,Grade_Scale!$D:$E,2,FALSE),""))
P7: =IF(OR(B7="SP",B7="RP",B7="CP",B7="SP/RP"),"P","H") | Q7: =IF(F7="",0,IFNA(VLOOKUP(F7,Trait_Polarity!$A:$C,2,FALSE),0))+IF(G7="",0,IFNA(VLOOKUP(G7,Trait_Polarity!$A:$C,2,FALSE),0)) | R7: =IF(F7="",0,IFNA(VLOOKUP(F7,Trait_Polarity!$A:$C,3,FALSE),0))+IF(G7="",0,IFNA(VLOOKUP(G7,Trait_Polarity!$A:$C,3,FALSE),0)) | S7: =IF(P7="P",(M7+N7+O7)/3,0.3*H7+0.3*I7+0.2*J7+0.1*K7+0.1*L7) | T7: =IF(P7="P",IFNA(VLOOKUP(B7,Pitcher_RoleAdj!$A:$B,2,FALSE),0),IFNA(VLOOKUP(B7,Hitter_PrimaryAdj!$A:$B,2,FALSE),0)) | U7: =IFNA(VLOOKUP(IF(C7="","(none)",C7),SecondaryAdj!$A:$B,2,FALSE),0) | V7: =IF(P7="P",0.7780+0.1628*S7+0.2957*Q7-0.1912*R7-0.1512*IF(D7="S",1,0)+0.1600*IF(E7="L",1,0)+0.0091*H7+0.0124*I7+0.0017*J7+T7+U7,-0.8294+0.1849*S7+0.1750*Q7-0.2969*R7+0.6924*IF(D7="S",1,0)+0.0457*IF(E7="L",1,0)+T7+U7) | W7: =MAX(0,MIN(16,ROUND(V7,0))) | X7: =IFNA(VLOOKUP(W7,Grade_Scale!$A:$B,2,FALSE),"F") | Z7: =IF(Y7="","",W7-IFNA(VLOOKUP(Y7,Grade_Scale!$D:$E,2,FALSE),""))
P8: =IF(OR(B8="SP",B8="RP",B8="CP",B8="SP/RP"),"P","H") | Q8: =IF(F8="",0,IFNA(VLOOKUP(F8,Trait_Polarity!$A:$C,2,FALSE),0))+IF(G8="",0,IFNA(VLOOKUP(G8,Trait_Polarity!$A:$C,2,FALSE),0)) | R8: =IF(F8="",0,IFNA(VLOOKUP(F8,Trait_Polarity!$A:$C,3,FALSE),0))+IF(G8="",0,IFNA(VLOOKUP(G8,Trait_Polarity!$A:$C,3,FALSE),0)) | S8: =IF(P8="P",(M8+N8+O8)/3,0.3*H8+0.3*I8+0.2*J8+0.1*K8+0.1*L8) | T8: =IF(P8="P",IFNA(VLOOKUP(B8,Pitcher_RoleAdj!$A:$B,2,FALSE),0),IFNA(VLOOKUP(B8,Hitter_PrimaryAdj!$A:$B,2,FALSE),0)) | U8: =IFNA(VLOOKUP(IF(C8="","(none)",C8),SecondaryAdj!$A:$B,2,FALSE),0) | V8: =IF(P8="P",0.7780+0.1628*S8+0.2957*Q8-0.1912*R8-0.1512*IF(D8="S",1,0)+0.1600*IF(E8="L",1,0)+0.0091*H8+0.0124*I8+0.0017*J8+T8+U8,-0.8294+0.1849*S8+0.1750*Q8-0.2969*R8+0.6924*IF(D8="S",1,0)+0.0457*IF(E8="L",1,0)+T8+U8) | W8: =MAX(0,MIN(16,ROUND(V8,0))) | X8: =IFNA(VLOOKUP(W8,Grade_Scale!$A:$B,2,FALSE),"F") | Z8: =IF(Y8="","",W8-IFNA(VLOOKUP(Y8,Grade_Scale!$D:$E,2,FALSE),""))
P9: =IF(OR(B9="SP",B9="RP",B9="CP",B9="SP/RP"),"P","H") | Q9: =IF(F9="",0,IFNA(VLOOKUP(F9,Trait_Polarity!$A:$C,2,FALSE),0))+IF(G9="",0,IFNA(VLOOKUP(G9,Trait_Polarity!$A:$C,2,FALSE),0)) | R9: =IF(F9="",0,IFNA(VLOOKUP(F9,Trait_Polarity!$A:$C,3,FALSE),0))+IF(G9="",0,IFNA(VLOOKUP(G9,Trait_Polarity!$A:$C,3,FALSE),0)) | S9: =IF(P9="P",(M9+N9+O9)/3,0.3*H9+0.3*I9+0.2*J9+0.1*K9+0.1*L9) | T9: =IF(P9="P",IFNA(VLOOKUP(B9,Pitcher_RoleAdj!$A:$B,2,FALSE),0),IFNA(VLOOKUP(B9,Hitter_PrimaryAdj!$A:$B,2,FALSE),0)) | U9: =IFNA(VLOOKUP(IF(C9="","(none)",C9),SecondaryAdj!$A:$B,2,FALSE),0) | V9: =IF(P9="P",0.7780+0.1628*S9+0.2957*Q9-0.1912*R9-0.1512*IF(D9="S",1,0)+0.1600*IF(E9="L",1,0)+0.0091*H9+0.0124*I9+0.0017*J9+T9+U9,-0.8294+0.1849*S9+0.1750*Q9-0.2969*R9+0.6924*IF(D9="S",1,0)+0.0457*IF(E9="L",1,0)+T9+U9) | W9: =MAX(0,MIN(16,ROUND(V9,0))) | X9: =IFNA(VLOOKUP(W9,Grade_Scale!$A:$B,2,FALSE),"F") | Z9: =IF(Y9="","",W9-IFNA(VLOOKUP(Y9,Grade_Scale!$D:$E,2,FALSE),""))
P10: =IF(OR(B10="SP",B10="RP",B10="CP",B10="SP/RP"),"P","H") | Q10: =IF(F10="",0,IFNA(VLOOKUP(F10,Trait_Polarity!$A:$C,2,FALSE),0))+IF(G10="",0,IFNA(VLOOKUP(G10,Trait_Polarity!$A:$C,2,FALSE),0)) | R10: =IF(F10="",0,IFNA(VLOOKUP(F10,Trait_Polarity!$A:$C,3,FALSE),0))+IF(G10="",0,IFNA(VLOOKUP(G10,Trait_Polarity!$A:$C,3,FALSE),0)) | S10: =IF(P10="P",(M10+N10+O10)/3,0.3*H10+0.3*I10+0.2*J10+0.1*K10+0.1*L10) | T10: =IF(P10="P",IFNA(VLOOKUP(B10,Pitcher_RoleAdj!$A:$B,2,FALSE),0),IFNA(VLOOKUP(B10,Hitter_PrimaryAdj!$A:$B,2,FALSE),0)) | U10: =IFNA(VLOOKUP(IF(C10="","(none)",C10),SecondaryAdj!$A:$B,2,FALSE),0) | V10: =IF(P10="P",0.7780+0.1628*S10+0.2957*Q10-0.1912*R10-0.1512*IF(D10="S",1,0)+0.1600*IF(E10="L",1,0)+0.0091*H10+0.0124*I10+0.0017*J10+T10+U10,-0.8294+0.1849*S10+0.1750*Q10-0.2969*R10+0.6924*IF(D10="S",1,0)+0.0457*IF(E10="L",1,0)+T10+U10) | W10: =MAX(0,MIN(16,ROUND(V10,0))) | X10: =IFNA(VLOOKUP(W10,Grade_Scale!$A:$B,2,FALSE),"F") | Z10: =IF(Y10="","",W10-IFNA(VLOOKUP(Y10,Grade_Scale!$D:$E,2,FALSE),""))
P11: =IF(OR(B11="SP",B11="RP",B11="CP",B11="SP/RP"),"P","H") | Q11: =IF(F11="",0,IFNA(VLOOKUP(F11,Trait_Polarity!$A:$C,2,FALSE),0))+IF(G11="",0,IFNA(VLOOKUP(G11,Trait_Polarity!$A:$C,2,FALSE),0)) | R11: =IF(F11="",0,IFNA(VLOOKUP(F11,Trait_Polarity!$A:$C,3,FALSE),0))+IF(G11="",0,IFNA(VLOOKUP(G11,Trait_Polarity!$A:$C,3,FALSE),0)) | S11: =IF(P11="P",(M11+N11+O11)/3,0.3*H11+0.3*I11+0.2*J11+0.1*K11+0.1*L11) | T11: =IF(P11="P",IFNA(VLOOKUP(B11,Pitcher_RoleAdj!$A:$B,2,FALSE),0),IFNA(VLOOKUP(B11,Hitter_PrimaryAdj!$A:$B,2,FALSE),0)) | U11: =IFNA(VLOOKUP(IF(C11="","(none)",C11),SecondaryAdj!$A:$B,2,FALSE),0) | V11: =IF(P11="P",0.7780+0.1628*S11+0.2957*Q11-0.1912*R11-0.1512*IF(D11="S",1,0)+0.1600*IF(E11="L",1,0)+0.0091*H11+0.0124*I11+0.0017*J11+T11+U11,-0.8294+0.1849*S11+0.1750*Q11-0.2969*R11+0.6924*IF(D11="S",1,0)+0.0457*IF(E11="L",1,0)+T11+U11) | W11: =MAX(0,MIN(16,ROUND(V11,0))) | X11: =IFNA(VLOOKUP(W11,Grade_Scale!$A:$B,2,FALSE),"F") | Z11: =IF(Y11="","",W11-IFNA(VLOOKUP(Y11,Grade_Scale!$D:$E,2,FALSE),""))
P12: =IF(OR(B12="SP",B12="RP",B12="CP",B12="SP/RP"),"P","H") | Q12: =IF(F12="",0,IFNA(VLOOKUP(F12,Trait_Polarity!$A:$C,2,FALSE),0))+IF(G12="",0,IFNA(VLOOKUP(G12,Trait_Polarity!$A:$C,2,FALSE),0)) | R12: =IF(F12="",0,IFNA(VLOOKUP(F12,Trait_Polarity!$A:$C,3,FALSE),0))+IF(G12="",0,IFNA(VLOOKUP(G12,Trait_Polarity!$A:$C,3,FALSE),0)) | S12: =IF(P12="P",(M12+N12+O12)/3,0.3*H12+0.3*I12+0.2*J12+0.1*K12+0.1*L12) | T12: =IF(P12="P",IFNA(VLOOKUP(B12,Pitcher_RoleAdj!$A:$B,2,FALSE),0),IFNA(VLOOKUP(B12,Hitter_PrimaryAdj!$A:$B,2,FALSE),0)) | U12: =IFNA(VLOOKUP(IF(C12="","(none)",C12),SecondaryAdj!$A:$B,2,FALSE),0) | V12: =IF(P12="P",0.7780+0.1628*S12+0.2957*Q12-0.1912*R12-0.1512*IF(D12="S",1,0)+0.1600*IF(E12="L",1,0)+0.0091*H12+0.0124*I12+0.0017*J12+T12+U12,-0.8294+0.1849*S12+0.1750*Q12-0.2969*R12+0.6924*IF(D12="S",1,0)+0.0457*IF(E12="L",1,0)+T12+U12) | W12: =MAX(0,MIN(16,ROUND(V12,0))) | X12: =IFNA(VLOOKUP(W12,Grade_Scale!$A:$B,2,FALSE),"F") | Z12: =IF(Y12="","",W12-IFNA(VLOOKUP(Y12,Grade_Scale!$D:$E,2,FALSE),""))
P13: =IF(OR(B13="SP",B13="RP",B13="CP",B13="SP/RP"),"P","H") | Q13: =IF(F13="",0,IFNA(VLOOKUP(F13,Trait_Polarity!$A:$C,2,FALSE),0))+IF(G13="",0,IFNA(VLOOKUP(G13,Trait_Polarity!$A:$C,2,FALSE),0)) | R13: =IF(F13="",0,IFNA(VLOOKUP(F13,Trait_Polarity!$A:$C,3,FALSE),0))+IF(G13="",0,IFNA(VLOOKUP(G13,Trait_Polarity!$A:$C,3,FALSE),0)) | S13: =IF(P13="P",(M13+N13+O13)/3,0.3*H13+0.3*I13+0.2*J13+0.1*K13+0.1*L13) | T13: =IF(P13="P",IFNA(VLOOKUP(B13,Pitcher_RoleAdj!$A:$B,2,FALSE),0),IFNA(VLOOKUP(B13,Hitter_PrimaryAdj!$A:$B,2,FALSE),0)) | U13: =IFNA(VLOOKUP(IF(C13="","(none)",C13),SecondaryAdj!$A:$B,2,FALSE),0) | V13: =IF(P13="P",0.7780+0.1628*S13+0.2957*Q13-0.1912*R13-0.1512*IF(D13="S",1,0)+0.1600*IF(E13="L",1,0)+0.0091*H13+0.0124*I13+0.0017*J13+T13+U13,-0.8294+0.1849*S13+0.1750*Q13-0.2969*R13+0.6924*IF(D13="S",1,0)+0.0457*IF(E13="L",1,0)+T13+U13) | W13: =MAX(0,MIN(16,ROUND(V13,0))) | X13: =IFNA(VLOOKUP(W13,Grade_Scale!$A:$B,2,FALSE),"F") | Z13: =IF(Y13="","",W13-IFNA(VLOOKUP(Y13,Grade_Scale!$D:$E,2,FALSE),""))
... P1001: =IF(OR(B1001="SP",B1001="RP",B1001="CP",B1001="SP/RP"),"P","H") | Q1001: =IF(F1001="",0,IFNA(VLOOKUP(F1001,Trait_Polarity!$A:$C,2,FALSE),0))+IF(G1001="",0,IFNA(VLOOKUP(G1001,Trait_Polarity!$A:$C,2,FALSE),0)) | R1001: =IF(F1001="",0,IFNA(VLOOKUP(F1001,Trait_Polarity!$A:$C,3,FALSE),0))+IF(G1001="",0,IFNA(VLOOKUP(G1001,Trait_Polarity!$A:$C,3,FALSE),0)) | S1001: =IF(P1001="P",(M1001+N1001+O1001)/3,0.3*H1001+0.3*I1001+0.2*J1001+0.1*K1001+0.1*L1001) | T1001: =IF(P1001="P",IFNA(VLOOKUP(B1001,Pitcher_RoleAdj!$A:$B,2,FALSE),0),IFNA(VLOOKUP(B1001,Hitter_PrimaryAdj!$A:$B,2,FALSE),0)) | U1001: =IFNA(VLOOKUP(IF(C1001="","(none)",C1001),SecondaryAdj!$A:$B,2,FALSE),0) | V1001: =IF(P1001="P",0.7780+0.1628*S1001+0.2957*Q1001-0.1912*R1001-0.1512*IF(D1001="S",1,0)+0.1600*IF(E1001="L",1,0)+0.0091*H1001+0.0124*I1001+0.0017*J1001+T1001+U1001,-0.8294+0.1849*S1001+0.1750*Q1001-0.2969*R1001+0.6924*IF(D1001="S",1,0)+0.0457*IF(E1001="L",1,0)+T1001+U1001) | W1001: =MAX(0,MIN(16,ROUND(V1001,0))) | X1001: =IFNA(VLOOKUP(W1001,Grade_Scale!$A:$B,2,FALSE),"F") | Z1001: =IF(Y1001="","",W1001-IFNA(VLOOKUP(Y1001,Grade_Scale!$D:$E,2,FALSE),""))

Sheet Generator
A1: Fictional Player Generator (same model as Calculator)
A3: Mode (H or P) | B3: H
A4: TargetGrade | B4: B
A5: PrimaryPos | B5: SS
A6: SecondaryPos | B6: 2B
A7: Bats | B7: R
A8: Throws | B8: R
A9: Trait1
A10: Trait2
A11: Pitcher BatPOW (optional)
A12: Pitcher BatCON (optional)
A13: Pitcher BatSPD (optional)
A15: TargetGradeIdx | B15: =IFNA(VLOOKUP(B4,Grade_Scale!$D:$E,2,FALSE),11)
A16: PosTraits | B16: =IF(B9="",0,IFNA(VLOOKUP(B9,Trait_Polarity!$A:$C,2,FALSE),0))+IF(B10="",0,IFNA(VLOOKUP(B10,Trait_Polarity!$A:$C,2,FALSE),0))
A17: NegTraits | B17: =IF(B9="",0,IFNA(VLOOKUP(B9,Trait_Polarity!$A:$C,3,FALSE),0))+IF(B10="",0,IFNA(VLOOKUP(B10,Trait_Polarity!$A:$C,3,FALSE),0))
A18: PrimaryAdj | B18: =IF(B3="P",IFNA(VLOOKUP(B5,Pitcher_RoleAdj!$A:$B,2,FALSE),0),IFNA(VLOOKUP(B5,Hitter_PrimaryAdj!$A:$B,2,FALSE),0))
A19: SecondaryAdj | B19: =IFNA(VLOOKUP(IF(B6="","(none)",B6),SecondaryAdj!$A:$B,2,FALSE),0)
A20: ConstantTerm | B20: =IF(B3="P",0.7780+0.2957*B16-0.1912*B17-0.1512*IF(B7="S",1,0)+0.1600*IF(B8="L",1,0)+0.0091*B11+0.0124*B12+0.0017*B13+B18+B19,-0.8294+0.1750*B16-0.2969*B17+0.6924*IF(B7="S",1,0)+0.0457*IF(B8="L",1,0)+B18+B19)
A21: RequiredBaseWeighted | B21: =IF(B3="P",(B15-B20)/0.1628,(B15-B20)/0.1849)
A23: HITTER random generator | D23: Edit any input in B3:B13, then recalc (or press Enter) to reroll RAND() outputs.
A24: POW | B24: =MAX(0,MIN(99,ROUND($B$21+C24+(RAND()-0.5)*20,0))) | C24: =IF($B$5="1B",15,IF($B$5="2B",-10,IF($B$5="SS",-10,IF($B$5="3B",10,IF($B$5="LF",10,IF($B$5="CF",-10,IF($B$5="RF",5,0)))))))
A25: CON | B25: =MAX(0,MIN(99,ROUND($B$21+C25+(RAND()-0.5)*20,0))) | C25: =IF($B$5="2B",5,0)
A26: SPD | B26: =MAX(0,MIN(99,ROUND($B$21+C26+(RAND()-0.5)*20,0))) | C26: =IF($B$5="C",-10,IF($B$5="1B",-10,IF($B$5="2B",5,IF($B$5="SS",5,IF($B$5="3B",-10,IF($B$5="CF",15,IF($B$5="RF",-5,0)))))))
A27: FLD | B27: =MAX(0,MIN(99,ROUND($B$21+C27+(RAND()-0.5)*20,0))) | C27: =IF($B$5="C",10,IF($B$5="1B",-5,IF($B$5="SS",10,IF($B$5="LF",-5,IF($B$5="CF",5,0)))))
A28: ARM | B28: =MAX(0,MIN(99,ROUND($B$21+C28+(RAND()-0.5)*20,0))) | C28: =IF($B$5="C",10,IF($B$5="SS",5,IF($B$5="3B",5,IF($B$5="LF",-5,IF($B$5="RF",10,0)))))
A29: Hitter BaseWeighted | B29: =0.3*B24+0.3*B25+0.2*B26+0.1*B27+0.1*B28
A30: Hitter Points | B30: =-0.8294+0.1849*B29+0.1750*B16-0.2969*B17+0.6924*IF(B7="S",1,0)+0.0457*IF(B8="L",1,0)+B18+B19
A31: Hitter GradeIdx | B31: =MAX(0,MIN(16,ROUND(B30,0)))
A32: Hitter Grade | B32: =IFNA(VLOOKUP(B31,Grade_Scale!$A:$B,2,FALSE),"F")
A35: PITCHER random generator
A36: BatPOW | B36: =IF(B11="",ROUND(RAND()*35,0),B11)
A37: BatCON | B37: =IF(B12="",ROUND(RAND()*40,0),B12)
A38: BatSPD | B38: =IF(B13="",ROUND(RAND()*60,0),B13)
A39: VEL | B39: =MAX(0,MIN(99,ROUND($B$21+C39+(RAND()-0.5)*20,0))) | C39: =IF($B$5="SP",-2,IF($B$5="CP",8,IF($B$5="SP/RP",3,2)))
A40: JNK | B40: =MAX(0,MIN(99,ROUND($B$21+C40+(RAND()-0.5)*20,0))) | C40: =IF($B$5="SP",-3,IF($B$5="CP",5,IF($B$5="SP/RP",2,1)))
A41: ACC | B41: =MAX(0,MIN(99,ROUND($B$21+C41+(RAND()-0.5)*20,0))) | C41: =IF($B$5="SP",5,IF($B$5="CP",-13,IF($B$5="SP/RP",0,-2)))
A42: Pitcher BaseWeighted | B42: =(B39+B40+B41)/3
A43: Pitcher Points | B43: =0.7780+0.1628*B42+0.2957*B16-0.1912*B17-0.1512*IF(B7="S",1,0)+0.1600*IF(B8="L",1,0)+0.0091*B36+0.0124*B37+0.0017*B38+B18+B19
A44: Pitcher GradeIdx | B44: =MAX(0,MIN(16,ROUND(B43,0)))
A45: Pitcher Grade | B45: =IFNA(VLOOKUP(B44,Grade_Scale!$A:$B,2,FALSE),"F")
...
